<?xml version="1.0" ?>
<robot xmlns:xacro="http://www.ros.org/wiki/xacro">
  

   
  <xacro:property name="base_inertia_radius" value="0.06"/>
  
   
  <xacro:property name="base_inertia_length" value="0.05"/>
  
   
  <xacro:property name="base_mass" value="4.0"/>
  
   
   
  <xacro:property name="shoulder_inertia_radius" value="0.075"/>
  
   
  <xacro:property name="shoulder_inertia_length" value="0.178"/>
  
   
  <xacro:property name="shoulder_mass" value="3.7"/>
  
   
  <xacro:property name="shoulder_x" value="0"/>
  
   
  <xacro:property name="shoulder_y" value="0"/>
  
   
  <xacro:property name="shoulder_z" value="0.089159"/>
  
   
  <xacro:property name="shoulder_roll" value="0"/>
  
   
  <xacro:property name="shoulder_pitch" value="0"/>
  
   
  <xacro:property name="shoulder_yaw" value="0"/>
  
   
  <xacro:property name="shoulder_pan_lower_limit" value="-6.2832"/>
  
   
  <xacro:property name="shoulder_pan_upper_limit" value="6.2832"/>
  
   
  <xacro:property name="shoulder_pan_velocity_limit" value="3.1416"/>
  
   
  <xacro:property name="shoulder_pan_effort_limit" value="150.0"/>
  
   
  <xacro:property name="shoulder_offset" value="0.13585"/>
  

   
  <xacro:property name="upper_arm_mass" value="8.393"/>
  
   
  <xacro:property name="upper_arm_inertia_offset" value="0.136"/>
  
   
  <xacro:property name="upperarm_inertia_radius" value="0.06"/>
  
   
  <xacro:property name="upperarm_inertia_length" value="0.425"/>
  
   
  <xacro:property name="upper_arm_x" value="0"/>
  
   
  <xacro:property name="upper_arm_y" value="0"/>
  
   
  <xacro:property name="upper_arm_z" value="0"/>
  
   
  <xacro:property name="upper_arm_roll" value="1.570796327"/>
  
   
  <xacro:property name="upper_arm_pitch" value="0"/>
  
   
  <xacro:property name="upper_arm_yaw" value="0"/>
  

   
  <xacro:property name="shoulder_lift_lower_limit" value="-6.2832"/>
  
   
  <xacro:property name="shoulder_lift_upper_limit" value="6.2832"/>
  
   
  <xacro:property name="shoulder_lift_velocity_limit" value="3.1416"/>
  
   
  <xacro:property name="shoulder_lift_effort_limit" value="150.0"/>
  

   
  <xacro:property name="forearm_inertia_radius" value="0.06"/>
  
    
  <xacro:property name="forearm_inertia_length" value="0.39225"/>
  
    
  <xacro:property name="elbow_offset" value="0.0165"/>
  
    
  <xacro:property name="forearm_mass" value="2.275"/>
  
    
  <xacro:property name="forearm_x" value="-0.425"/>
  
    
  <xacro:property name="forearm_y" value="0"/>
  
    
  <xacro:property name="forearm_z" value="0"/>
  
    
  <xacro:property name="forearm_roll" value="0"/>
  
    
  <xacro:property name="forearm_pitch" value="0"/>
  
    
  <xacro:property name="forearm_yaw" value="0"/>
  

    
  <xacro:property name="elbow_joint_lower_limit" value="-3.1416"/>
  
    
  <xacro:property name="elbow_joint_upper_limit" value="3.1416"/>
  
    
  <xacro:property name="elbow_joint_velocity_limit" value="3.1416"/>
  
    
  <xacro:property name="elbow_joint_effort_limit" value="150.0"/>
  

    
  <xacro:property name="wrist_1_lower_limit" value="-6.2832"/>
  
    
  <xacro:property name="wrist_1_upper_limit" value="6.2832"/>
  
    
  <xacro:property name="wrist_1_velocity_limit" value="3.1416"/>
  
    
  <xacro:property name="wrist_1_effort_limit" value="28.0"/>
  
    
  <xacro:property name="wrist_1_x" value="-0.39225"/>
  
    
  <xacro:property name="wrist_1_y" value="0"/>
  
    
  <xacro:property name="wrist_1_z" value="0.10915"/>
  
    
  <xacro:property name="wrist_1_roll" value="0"/>
  
    
  <xacro:property name="wrist_1_pitch" value="0"/>
  
    
  <xacro:property name="wrist_1_yaw" value="0"/>
  
    
  <xacro:property name="wrist_1_mass" value="1.219"/>
  
    
  <xacro:property name="wrist_1_inertia_radius" value="0.06"/>
  
    
  <xacro:property name="wrist_1_inertia_length" value="0.095"/>
  
    
  <xacro:property name="wrist_1_visual_offset" value="-0.093"/>
  

    
  <xacro:property name="wrist_2_x" value="0"/>
  
    
  <xacro:property name="wrist_2_y" value="-0.09465"/>
  
    
  <xacro:property name="wrist_2_z" value="-1.941303950897609e-11"/>
  
    
  <xacro:property name="wrist_2_roll" value="1.570796327"/>
  
    
  <xacro:property name="wrist_2_pitch" value="0"/>
  
    
  <xacro:property name="wrist_2_yaw" value="0"/>
  
    
  <xacro:property name="wrist_2_inertia_radius" value="0.06"/>
  
    
  <xacro:property name="wrist_2_inertia_length" value="0.095"/>
  
    
  <xacro:property name="wrist_2_visual_offset" value="-0.095"/>
  
    
  <xacro:property name="wrist_2_mass" value="1.219"/>
  
    
  <xacro:property name="wrist_2_lower_limit" value="-6.2832"/>
  
    
  <xacro:property name="wrist_2_upper_limit" value="6.2832"/>
  
    
  <xacro:property name="wrist_2_velocity_limit" value="3.1416"/>
  
    
  <xacro:property name="wrist_2_effort_limit" value="28.0"/>
  
    
    
  <xacro:property name="wrist_3_x" value="0"/>
  
    
  <xacro:property name="wrist_3_y" value="0.0823"/>
  
    
  <xacro:property name="wrist_3_z" value="-1.688001216681175e-11"/>
  
    
  <xacro:property name="wrist_3_roll" value="1.570796326589793"/>
  
    
  <xacro:property name="wrist_3_pitch" value="3.141592653589793"/>
  
    
  <xacro:property name="wrist_3_yaw" value="3.141592653589793"/>
  
    
  <xacro:property name="wrist_3_mass" value="0.1879"/>
  
    
  <xacro:property name="wrist_3_visual_offset" value="-0.081"/>
  
    
  <xacro:property name="wrist_3_inertia_radius" value="0.0375"/>
  
    
  <xacro:property name="wrist_3_inertia_length" value="0.0305"/>
  
    
  <xacro:property name="wrist_3_lower_limit" value="-6.2832"/>
  
    
  <xacro:property name="wrist_3_upper_limit" value="6.2832"/>
  
    
  <xacro:property name="wrist_3_velocity_limit" value="3.1416"/>
  
    
  <xacro:property name="wrist_3_effort_limit" value="28.0"/>
  
    
  <xacro:property name="safety_limits" default="false"/>
  
    
  <xacro:property name="safety_pos_margin" default="0.15"/>
  
    
  <xacro:property name="safety_k_position" default="20"/>
  


  <!---->
  
 
  <xacro:macro name="ur5_ros2control" params="prefix EE_no">
    

    
    <!-- ROS2_CONTROL tag name: -->
    
    
    <xacro:property name="name" value="GazeboSystem"/>
    

    
    <!-- ===== Gazebo ROS2_CONTROL plugin ===== -->
    
    
    <!-- No End-Effector: -->
    
    
    <xacro:if value="${EE_no}">
      
      
      <gazebo>
        
        
        <plugin filename="libgazebo_ros2_control.so" name="gazebo_ros2_control">
          
          
          <robot_sim_type>gazebo_ros2_control/GazeboSystem</robot_sim_type>
          
          
          <parameters>ur5_controller.yaml</parameters>
          
        
        </plugin>
        
      
      </gazebo>
      
    
    </xacro:if>
    
    
    
    <!-- ========== ROS2 CONTROL ========== -->
    

    
    <ros2_control name="${name}" type="system">
      

      
      <hardware>
        
        
        <plugin>gazebo_ros2_control/GazeboSystem</plugin>
        
      
      </hardware>
      

      
      <joint name="shoulder_pan_joint">
        
        
        <command_interface name="position">
          
          
          <param name="min">${-2*pi}</param>
          
          
          <param name="max">${2*pi}</param>
          
        
        </command_interface>
        
        
        <command_interface name="velocity">
          
          
          <param name="min">-3.15</param>
          
          
          <param name="max">3.15</param>
          
        
        </command_interface>
        
        
        <state_interface name="position"/>
        
        
        <state_interface name="velocity"/>
        
        
        <state_interface name="effort"/>
        
        
        <!-- <param name="initial_position">${initial_positions['shoulder_pan_joint']}</param>   initial position for the FakeSystem -->
        
      
      </joint>
      
      
      <joint name="shoulder_lift_joint">
        
        
        <command_interface name="position">
          
          
          <param name="min">${-2*pi}</param>
          
          
          <param name="max">${2*pi}</param>
          
        
        </command_interface>
        
        
        <command_interface name="velocity">
          
          
          <param name="min">-3.15</param>
          
          
          <param name="max">3.15</param>
          
        
        </command_interface>
        
        
        <state_interface name="position"/>
        
        
        <state_interface name="velocity"/>
        
        
        <state_interface name="effort"/>
        
        
        <!-- <param name="initial_position">${initial_positions['shoulder_lift_joint']}</param>   initial position for the FakeSystem -->
        
      
      </joint>
      
      
      <joint name="elbow_joint">
        
        
        <command_interface name="position">
          
          
          <param name="min">${-pi}</param>
          
          
          <param name="max">${pi}</param>
          
        
        </command_interface>
        
        
        <command_interface name="velocity">
          
          
          <param name="min">-3.15</param>
          
          
          <param name="max">3.15</param>
          
        
        </command_interface>
        
        
        <state_interface name="position"/>
        
        
        <state_interface name="velocity"/>
        
        
        <state_interface name="effort"/>
        
        
        <!-- <param name="initial_position">${initial_positions['elbow_joint']}</param>   initial position for the FakeSystem -->
        
      
      </joint>
      
      
      <joint name="wrist_1_joint">
        
        
        <command_interface name="position">
          
          
          <param name="min">${-2*pi}</param>
          
          
          <param name="max">${2*pi}</param>
          
        
        </command_interface>
        
        
        <command_interface name="velocity">
          
          
          <param name="min">-3.2</param>
          
          
          <param name="max">3.2</param>
          
        
        </command_interface>
        
        
        <state_interface name="position"/>
        
        
        <state_interface name="velocity"/>
        
        
        <state_interface name="effort"/>
        
        
        <!-- <param name="initial_position">${initial_positions['wrist_1_joint']}</param>   initial position for the FakeSystem -->
        
      
      </joint>
      
      
      <joint name="wrist_2_joint">
        
        
        <command_interface name="position">
          
          
          <param name="min">${-2*pi}</param>
          
          
          <param name="max">${2*pi}</param>
          
        
        </command_interface>
        
        
        <command_interface name="velocity">
          
          
          <param name="min">-3.2</param>
          
          
          <param name="max">3.2</param>
          
        
        </command_interface>
        
        
        <state_interface name="position"/>
        
        
        <state_interface name="velocity"/>
        
        
        <state_interface name="effort"/>
        
        
        <!-- <param name="initial_position">${initial_positions['wrist_2_joint']}</param>   initial position for the FakeSystem -->
        
      
      </joint>
      
      
      <joint name="wrist_3_joint">
        
        
        <command_interface name="position">
          
          
          <param name="min">${-2*pi}</param>
          
          
          <param name="max">${2*pi}</param>
          
        
        </command_interface>
        
        
        <command_interface name="velocity">
          
          
          <param name="min">-3.2</param>
          
          
          <param name="max">3.2</param>
          
        
        </command_interface>
        
        
        <state_interface name="position"/>
        
        
        <state_interface name="velocity"/>
        
        
        <state_interface name="effort"/>
        
        
        <!-- <param name="initial_position">${initial_positions['wrist_3_joint']}</param>   initial position for the FakeSystem -->
        
      
      </joint>
      

    
    </ros2_control>
    

    
    <gazebo reference="shoulder_link">
      
      
      <selfCollide>false</selfCollide>
      
    
    </gazebo>
    
    
    <gazebo reference="upper_arm_link">
      
      
      <selfCollide>false</selfCollide>
      
    
    </gazebo>
    
    
    <gazebo reference="forearm_link">
      
      
      <selfCollide>false</selfCollide>
      
    
    </gazebo>
    
    
    <gazebo reference="wrist_1_link">
      
      
      <selfCollide>false</selfCollide>
      
    
    </gazebo>
    
    
    <gazebo reference="wrist_3_link">
      
      
      <selfCollide>false</selfCollide>
      
    
    </gazebo>
    
    
    <gazebo reference="wrist_2_link">
      
      
      <selfCollide>false</selfCollide>
      
    
    </gazebo>
    
    
    <gazebo reference="ee_link">
      
      
      <selfCollide>false</selfCollide>
      
    
    </gazebo>
    

  
  </xacro:macro>
  




  <!---->
  

    

  
  <xacro:macro name="cylinder_inertial2" params="radius length mass *origin">
    
    
    <inertial>
      
      
      <mass value="${mass}"/>
      
      
      <xacro:insert_block name="origin"/>
      
      
      <inertia ixx="${0.0833333 * mass * (3 * radius * radius + length * length)}" ixy="0.0" ixz="0.0" iyy="${0.0833333 * mass * (3 * radius * radius + length * length)}" iyz="0.0" izz="${0.5 * mass * radius * radius}"/>
      
    
    </inertial>
    
  
  </xacro:macro>
  


    
  <xacro:macro name="ur5_transmission" params="prefix">
    

    
    <transmission name="${prefix}shoulder_pan_trans">
      
      
      <type>transmission_interface/SimpleTransmission</type>
      
      
      <joint name="${prefix}shoulder_pan_joint">
        
        
        <hardwareInterface>hardware_interface/PositionJointInterface</hardwareInterface>
        
      
      </joint>
      
      
      <actuator name="${prefix}shoulder_pan_motor">
        
        
        <mechanicalReduction>1</mechanicalReduction>
        
      
      </actuator>
      
    
    </transmission>
    

    
    <transmission name="${prefix}shoulder_lift_trans">
      
      
      <type>transmission_interface/SimpleTransmission</type>
      
      
      <joint name="${prefix}shoulder_lift_joint">
        
        
        <hardwareInterface>hardware_interface/PositionJointInterface</hardwareInterface>
        
      
      </joint>
      
      
      <actuator name="${prefix}shoulder_lift_motor">
        
        
        <mechanicalReduction>1</mechanicalReduction>
        
      
      </actuator>
      
    
    </transmission>
    

    
    <transmission name="${prefix}elbow_trans">
      
      
      <type>transmission_interface/SimpleTransmission</type>
      
      
      <joint name="${prefix}elbow_joint">
        
        
        <hardwareInterface>hardware_interface/PositionJointInterface</hardwareInterface>
        
      
      </joint>
      
      
      <actuator name="${prefix}elbow_motor">
        
        
        <mechanicalReduction>1</mechanicalReduction>
        
      
      </actuator>
      
    
    </transmission>
    

    
    <transmission name="${prefix}wrist_1_trans">
      
      
      <type>transmission_interface/SimpleTransmission</type>
      
      
      <joint name="${prefix}wrist_1_joint">
        
        
        <hardwareInterface>hardware_interface/PositionJointInterface</hardwareInterface>
        
      
      </joint>
      
      
      <actuator name="${prefix}wrist_1_motor">
        
        
        <mechanicalReduction>1</mechanicalReduction>
        
      
      </actuator>
      
    
    </transmission>
    

    
    <transmission name="${prefix}wrist_2_trans">
      
      
      <type>transmission_interface/SimpleTransmission</type>
      
      
      <joint name="${prefix}wrist_2_joint">
        
        
        <hardwareInterface>hardware_interface/PositionJointInterface</hardwareInterface>
        
      
      </joint>
      
      
      <actuator name="${prefix}wrist_2_motor">
        
        
        <mechanicalReduction>1</mechanicalReduction>
        
      
      </actuator>
      
    
    </transmission>
    

    
    <transmission name="${prefix}wrist_3_trans">
      
      
      <type>transmission_interface/SimpleTransmission</type>
      
      
      <joint name="${prefix}wrist_3_joint">
        
        
        <hardwareInterface>hardware_interface/PositionJointInterface</hardwareInterface>
        
      
      </joint>
      
      
      <actuator name="${prefix}wrist_3_motor">
        
        
        <mechanicalReduction>1</mechanicalReduction>
        
      
      </actuator>
      
    
    </transmission>
    

  
  </xacro:macro>
  
  
  <xacro:ur5_transmission prefix=""/>
  

 
 
  <link name="base_ur5">
    
   
    
    <visual>
      
        
      <origin xyz="0 0 0" rpy="0 0 ${pi}"/>
      
        
      <geometry>
        
          
        <mesh filename="package://my_robot_description/meshes/visual/base.dae"/>
        
        
      </geometry>
      
        
      <material name="LightGrey">
        
          
        <color rgba="0.7 0.7 0.7 1.0"/>
        
        
      </material>
      
    
    </visual>
    
    
    <collision>
      
        
      <origin xyz="0 0 0" rpy="0 0 ${pi}"/>
      
        
      <geometry>
        
          
        <mesh filename="package://my_robot_description/meshes/collision/base.stl"/>
        
        
      </geometry>
      
    
    </collision>
    
    
    <xacro:cylinder_inertial2 radius="${base_inertia_radius}" length="${base_inertia_length}" mass="${base_mass}">
      
        
      <origin xyz="0 0 0" rpy="0 0 0"/>
      
      
    </xacro:cylinder_inertial2>
    
 
    <inertial>
      <mass value="1.0"/>
      <origin xyz="0 0 0" rpy="0 0 0"/>
      <inertia ixx="0.01" ixy="0.0" ixz="0.0" iyy="0.01" iyz="0.0" izz="0.01"/>
    </inertial>
  </link>
  
 
 
  <link name="shoulder_link">
    
      
    <visual>
      
        
      <origin xyz="0 0 0" rpy="0 0 ${pi}"/>
      
        
      <geometry>
        
          
        <mesh filename="package://my_robot_description/meshes/visual/shoulder.dae"/>
        
        
      </geometry>
      
        
      <material name="LightGrey">
        
          
        <color rgba="0.7 0.7 0.7 1.0"/>
        
        
      </material>
      
      
    </visual>
    
      
    <collision>
      
        
      <origin xyz="0 0 0" rpy="0 0 ${pi}"/>
      
        
      <geometry>
        
          
        <mesh filename="package://my_robot_description/meshes/collision/shoulder.stl"/>
        
        
      </geometry>
      
      
    </collision>
    
      
    <xacro:cylinder_inertial2 radius="${shoulder_inertia_radius}" length="${shoulder_inertia_length}" mass="${shoulder_mass}">
      
        
      <origin xyz="0 0 0" rpy="0 0 0"/>
      
      
    </xacro:cylinder_inertial2>
    
    
    <inertial>
      <mass value="1.0"/>
      <origin xyz="0 0 0" rpy="0 0 0"/>
      <inertia ixx="0.01" ixy="0.0" ixz="0.0" iyy="0.01" iyz="0.0" izz="0.01"/>
    </inertial>
  </link>
  


  
  <link name="upper_arm_link">
    
      
    <visual>
      
        
      <origin xyz="0 0 ${shoulder_offset}" rpy="${pi/2} 0 ${-pi/2}"/>
      
        
      <geometry>
        
          
        <mesh filename="package://my_robot_description/meshes/visual/upperarm.dae"/>
        
        
      </geometry>
      
        
      <material name="LightGrey">
        
          
        <color rgba="0.7 0.7 0.7 1.0"/>
        
        
      </material>
      
      
    </visual>
    
      
    <collision>
      
        
      <origin xyz="0 0 ${shoulder_offset}" rpy="${pi/2} 0 ${-pi/2}"/>
      
        
      <geometry>
        
          
        <mesh filename="package://my_robot_description/meshes/collision/upperarm.stl"/>
        
        
      </geometry>
      
      
    </collision>
    
      
    <xacro:cylinder_inertial2 radius="${upperarm_inertia_radius}" length="${upperarm_inertia_length}" mass="${upper_arm_mass}">
      
        
      <origin xyz="${-0.5 * upperarm_inertia_length} 0.0 ${upper_arm_inertia_offset}" rpy="0 ${pi/2} 0"/>
      
      
    </xacro:cylinder_inertial2>
    
  
    <inertial>
      <mass value="1.0"/>
      <origin xyz="0 0 0" rpy="0 0 0"/>
      <inertia ixx="0.01" ixy="0.0" ixz="0.0" iyy="0.01" iyz="0.0" izz="0.01"/>
    </inertial>
  </link>
  

  
  <link name="forearm_link">
    
      
    <visual>
      
        
      <origin xyz="0 0 ${elbow_offset}" rpy="${pi/2} 0 ${-pi/2}"/>
      
        
      <geometry>
        
          
        <mesh filename="package://my_robot_description/meshes/visual/forearm.dae"/>
        
        
      </geometry>
      
        
      <material name="LightGrey">
        
          
        <color rgba="0.7 0.7 0.7 1.0"/>
        
        
      </material>
      
      
    </visual>
    
      
    <collision>
      
        
      <origin xyz="0 0 ${elbow_offset}" rpy="${pi/2} 0 ${-pi/2}"/>
      
        
      <geometry>
        
          
        <mesh filename="package://my_robot_description/meshes/collision/forearm.stl"/>
        
        
      </geometry>
      
      
    </collision>
    
      
    <xacro:cylinder_inertial2 radius="${forearm_inertia_radius}" length="${forearm_inertia_length}" mass="${forearm_mass}">
      
        
      <origin xyz="${-0.5 * forearm_inertia_length} 0.0 ${elbow_offset}" rpy="0 ${pi/2} 0"/>
      
      
    </xacro:cylinder_inertial2>
    
  
    <inertial>
      <mass value="1.0"/>
      <origin xyz="0 0 0" rpy="0 0 0"/>
      <inertia ixx="0.01" ixy="0.0" ixz="0.0" iyy="0.01" iyz="0.0" izz="0.01"/>
    </inertial>
  </link>
  

  
  <link name="wrist_1_link">
    
      
    <visual>
      
        
      <origin xyz="0 0 ${wrist_1_visual_offset}" rpy="${pi/2} 0 0"/>
      
        
      <geometry>
        
          
        <mesh filename="package://my_robot_description/meshes/visual/wrist1.dae"/>
        
        
      </geometry>
      
        
      <material name="LightGrey">
        
          
        <color rgba="0.7 0.7 0.7 1.0"/>
        
        
      </material>
      
      
    </visual>
    
      
    <collision>
      
        
      <origin xyz="0 0 ${wrist_1_visual_offset}" rpy="${pi/2} 0 0"/>
      
        
      <geometry>
        
          
        <mesh filename="package://my_robot_description/meshes/collision/wrist1.stl"/>
        
        
      </geometry>
      
      
    </collision>
    
      
    <xacro:cylinder_inertial2 radius="${wrist_1_inertia_radius}" length="${wrist_1_inertia_length}" mass="${wrist_1_mass}">
      
        
      <origin xyz="0 0 0" rpy="0 0 0"/>
      
      
    </xacro:cylinder_inertial2>
    
  
    <inertial>
      <mass value="1.0"/>
      <origin xyz="0 0 0" rpy="0 0 0"/>
      <inertia ixx="0.01" ixy="0.0" ixz="0.0" iyy="0.01" iyz="0.0" izz="0.01"/>
    </inertial>
  </link>
  


  
  <link name="wrist_2_link">
    
      
    <visual>
      
        
      <origin xyz="0 0 ${wrist_2_visual_offset}" rpy="0 0 0"/>
      
        
      <geometry>
        
          
        <mesh filename="package://my_robot_description/meshes/visual/wrist2.dae"/>
        
        
      </geometry>
      
        
      <material name="LightGrey">
        
          
        <color rgba="0.7 0.7 0.7 1.0"/>
        
        
      </material>
      
      
    </visual>
    
      
    <collision>
      
        
      <origin xyz="0 0 ${wrist_2_visual_offset}" rpy="0 0 0"/>
      
        
      <geometry>
        
          
        <mesh filename="package://my_robot_description/meshes/collision/wrist2.stl"/>
        
        
      </geometry>
      
      
    </collision>
    
      
    <xacro:cylinder_inertial2 radius="${wrist_2_inertia_radius}" length="${wrist_2_inertia_length}" mass="${wrist_2_mass}">
      
        
      <origin xyz="0 0 0" rpy="0 0 0"/>
      
      
    </xacro:cylinder_inertial2>
    
  
    <inertial>
      <mass value="1.0"/>
      <origin xyz="0 0 0" rpy="0 0 0"/>
      <inertia ixx="0.01" ixy="0.0" ixz="0.0" iyy="0.01" iyz="0.0" izz="0.01"/>
    </inertial>
  </link>
  

  
  <link name="wrist_3_link">
    
      
    <visual>
      
        
      <origin xyz="0 0 ${wrist_3_visual_offset}" rpy="${pi/2} 0 0"/>
      
        
      <geometry>
        
          
        <mesh filename="package://my_robot_description/meshes/visual/wrist3.dae"/>
        
        
      </geometry>
      
        
      <material name="LightGrey">
        
          
        <color rgba="0.7 0.7 0.7 1.0"/>
        
        
      </material>
      
      
    </visual>
    
      
    <collision>
      
        
      <origin xyz="0 0 ${wrist_3_visual_offset}" rpy="${pi/2} 0 0"/>
      
        
      <geometry>
        
          
        <mesh filename="package://my_robot_description/meshes/collision/wrist3.stl"/>
        
        
      </geometry>
      
      
    </collision>
    
      
    <xacro:cylinder_inertial2 radius="${wrist_3_inertia_radius}" length="${wrist_3_inertia_length}" mass="${wrist_3_mass}">
      
        
      <origin xyz="0.0 0.0 ${-0.5 * wrist_3_inertia_length}" rpy="0 0 0"/>
      
      
    </xacro:cylinder_inertial2>
    
  
    <inertial>
      <mass value="1.0"/>
      <origin xyz="0 0 0" rpy="0 0 0"/>
      <inertia ixx="0.01" ixy="0.0" ixz="0.0" iyy="0.01" iyz="0.0" izz="0.01"/>
    </inertial>
  </link>
    

   
  <!--<link name="base_footprint"/> -->
  
    
  <joint name="base_joint2" type="fixed">
    
        
    <parent link="lidar_link2"/>
    
        
    <child link="base_ur5"/>
    
        
        
    <origin xyz="0 0 ${lidar_length2 }" rpy="0 0 ${pi}"/>
    
    
  </joint>
   

    
  <joint name="shoulder_pan_joint" type="revolute">
    
      
    <parent link="base_ur5"/>
    
      
    <child link="shoulder_link"/>
    
      
    <origin xyz="${shoulder_x} ${shoulder_y} ${shoulder_z}" rpy="${shoulder_roll} ${shoulder_pitch} ${shoulder_yaw}"/>
    
      
    <axis xyz="0 0 1"/>
    
      
    <limit lower="${shoulder_pan_lower_limit}" upper="${shoulder_pan_upper_limit}" effort="${shoulder_pan_effort_limit}" velocity="${shoulder_pan_velocity_limit}"/>
    
      
    <xacro:if value="${safety_limits}">
      
         
      <safety_controller soft_lower_limit="${shoulder_pan_lower_limit + safety_pos_margin}" soft_upper_limit="${shoulder_pan_upper_limit - safety_pos_margin}" k_position="${safety_k_position}" k_velocity="0.0"/>
      
      
    </xacro:if>
    
      
    <dynamics damping="50.0" friction="1.0"/>
    
    
  </joint>
  

    
  <joint name="shoulder_lift_joint" type="revolute">
    
      
    <parent link="shoulder_link"/>
    
      
    <child link="upper_arm_link"/>
    
      
    <origin xyz="${upper_arm_x} ${upper_arm_y} ${upper_arm_z}" rpy="${upper_arm_roll} ${upper_arm_pitch} ${upper_arm_yaw}"/>
    
      
    <axis xyz="0 0 1"/>
    
      
    <limit lower="${shoulder_lift_lower_limit}" upper="${shoulder_lift_upper_limit}" effort="${shoulder_lift_effort_limit}" velocity="${shoulder_lift_velocity_limit}"/>
    
      
    <xacro:if value="${safety_limits}">
      
         
      <safety_controller soft_lower_limit="${shoulder_lift_lower_limit + safety_pos_margin}" soft_upper_limit="${shoulder_lift_upper_limit - safety_pos_margin}" k_position="${safety_k_position}" k_velocity="0.0"/>
      
      
    </xacro:if>
    
      
    <dynamics damping="50.0" friction="1.0"/>
    
    
  </joint>
  
   

    
  <joint name="elbow_joint" type="revolute">
    
      
    <parent link="upper_arm_link"/>
    
      
    <child link="forearm_link"/>
    
      
    <origin xyz="${forearm_x} ${forearm_y} ${forearm_z}" rpy="${forearm_roll} ${forearm_pitch} ${forearm_yaw}"/>
    
      
    <axis xyz="0 0 1"/>
    
      
    <limit lower="${elbow_joint_lower_limit}" upper="${elbow_joint_upper_limit}" effort="${elbow_joint_effort_limit}" velocity="${elbow_joint_velocity_limit}"/>
    
      
    <xacro:if value="${safety_limits}">
      
         
      <safety_controller soft_lower_limit="${elbow_joint_lower_limit + safety_pos_margin}" soft_upper_limit="${elbow_joint_upper_limit - safety_pos_margin}" k_position="${safety_k_position}" k_velocity="0.0"/>
      
      
    </xacro:if>
    
      
    <dynamics damping="10.0" friction="1.0"/>
    
    
  </joint>
  

    
  <joint name="wrist_1_joint" type="revolute">
    
      
    <parent link="forearm_link"/>
    
      
    <child link="wrist_1_link"/>
    
      
    <origin xyz="${wrist_1_x} ${wrist_1_y} ${wrist_1_z}" rpy="${wrist_1_roll} ${wrist_1_pitch} ${wrist_1_yaw}"/>
    
      
    <axis xyz="0 0 1"/>
    
      
    <limit lower="${wrist_1_lower_limit}" upper="${wrist_1_upper_limit}" effort="${wrist_1_effort_limit}" velocity="${wrist_1_velocity_limit}"/>
    
      
    <xacro:if value="${safety_limits}">
      
         
      <safety_controller soft_lower_limit="${wrist_1_lower_limit + safety_pos_margin}" soft_upper_limit="${wrist_1_upper_limit - safety_pos_margin}" k_position="${safety_k_position}" k_velocity="0.0"/>
      
      
    </xacro:if>
    
      
    <dynamics damping="5.0" friction="1.0"/>
    
    
  </joint>
  

     
  <joint name="wrist_2_joint" type="revolute">
    
      
    <parent link="wrist_1_link"/>
    
      
    <child link="wrist_2_link"/>
    
      
    <origin xyz="${wrist_2_x} ${wrist_2_y} ${wrist_2_z}" rpy="${wrist_2_roll} ${wrist_2_pitch} ${wrist_2_yaw}"/>
    
      
    <axis xyz="0 0 1"/>
    
      
    <limit lower="${wrist_2_lower_limit}" upper="${wrist_2_upper_limit}" effort="${wrist_2_effort_limit}" velocity="${wrist_2_velocity_limit}"/>
    
      
    <xacro:if value="${safety_limits}">
      
         
      <safety_controller soft_lower_limit="${wrist_2_lower_limit + safety_pos_margin}" soft_upper_limit="${wrist_2_upper_limit - safety_pos_margin}" k_position="${safety_k_position}" k_velocity="0.0"/>
      
      
    </xacro:if>
    
      
    <dynamics damping="2.0" friction="1.0"/>
    
    
  </joint>
  

    
  <joint name="wrist_3_joint" type="revolute">
    
      
    <parent link="wrist_2_link"/>
    
      
    <child link="wrist_3_link"/>
    
      
    <origin xyz="${wrist_3_x} ${wrist_3_y} ${wrist_3_z}" rpy="${wrist_3_roll} ${wrist_3_pitch} ${wrist_3_yaw}"/>
    
      
    <axis xyz="0 0 1"/>
    
      
    <limit lower="${wrist_3_lower_limit}" upper="${wrist_3_upper_limit}" effort="${wrist_3_effort_limit}" velocity="${wrist_3_velocity_limit}"/>
    
      
    <xacro:if value="${safety_limits}">
      
         
      <safety_controller soft_lower_limit="${wrist_3_lower_limit + safety_pos_margin}" soft_upper_limit="${wrist_3_upper_limit - safety_pos_margin}" k_position="${safety_k_position}" k_velocity="0.0"/>
      
      
    </xacro:if>
    
      
    <dynamics damping="1.0" friction="1.0"/>
    
    
  </joint>
  
 

   
  <gazebo>
    
    
    <plugin name="gazebo_ros_joint_state_publisher" filename="libgazebo_ros_joint_state_publisher.so">
      
      
       
      <update_rate>10</update_rate>
      

     
       
      <joint_name>shoulder_pan_joint</joint_name>
      
       
      <joint_name>shoulder_lift_joint</joint_name>
      
       
      <joint_name>elbow_joint</joint_name>
      
       
      <joint_name>wrist_1_joint</joint_name>
      
       
      <joint_name>wrist_2_joint</joint_name>
      
       
      <joint_name>wrist_3_joint</joint_name>
      

    
    </plugin>
    
  
  </gazebo>
  


</robot>
